<?xml version="1.0" encoding="utf-8"?>
<!-- =================================================================================== -->
<!-- |    This document was autogenerated by xacro from arm_urdf.xacro                 | -->
<!-- |    EDITING THIS FILE BY HAND IS NOT RECOMMENDED                                 | -->
<!-- =================================================================================== -->
<robot name="test_robot">
  <link name="world"/>
  <joint name="fix" type="fixed">
    <parent link="world"/>
    <child link="base"/>
  </joint>
  <link name="base">
    <visual>
      <geometry>
        <box size="1 1 0.1"/>
      </geometry>
      <origin rpy="0 0 0" xyz="0 0 0.05"/>
      <material name="white">
        <color rgba="1 1 1 1"/>
      </material>
    </visual>
    <collision>
      <geometry>
        <box size="1 1 0.1"/>
      </geometry>
      <origin rpy="0 0 0" xyz="0 0 0.05"/>
    </collision>
    <inertial>
      <mass value="1.6"/>
      <origin rpy="0 0 0" xyz="0 0 0.0"/>
      <inertia ixx="0.006051" ixy="0" ixz="0" iyy="0.002" iyz="0" izz="0.009098"/>
    </inertial>
  </link>
  <link name="upperarm">
    <visual>
      <geometry>
        <cylinder length="0.7" radius="0.084"/>
      </geometry>
      <origin rpy="0 0 0" xyz="0 0 0.35"/>
      <material name="gray">
        <color rgba="0.8 0.8 0.8 0.5"/>
      </material>
    </visual>
    <collision>
      <geometry>
        <cylinder length="0.63" radius="0.084"/>
      </geometry>
      <origin rpy="0 0 0" xyz="0 0 0.35"/>
    </collision>
    <inertial>
      <mass value="1.6"/>
      <origin rpy="0 0 0" xyz="0 0 0.0"/>
      <inertia ixx="0.006051" ixy="0" ixz="0" iyy="0.002" iyz="0" izz="0.009098"/>
    </inertial>
  </link>
  <joint name="base_joint" type="continuous">
    <origin rpy="0 0 0" xyz="0 0 0"/>
    <axis xyz="0 0 1"/>
    <parent link="base"/>
    <child link="upperarm"/>
  </joint>
  <transmission name="tranbj">
    <type>transmission_interface/SimpleTransmission</type>
    <joint name="base_joint">
      <hardwareInterface>hardware_interface/PositionJointInterface</hardwareInterface>
    </joint>
    <actuator name="motorbj">
      <hardwareInterface>hardware_interface/PositionJointInterface</hardwareInterface>
      <mechanicalReduction>1</mechanicalReduction>
    </actuator>
  </transmission>
  <link name="upperball">
    <visual>
      <geometry>
        <sphere radius="0.14"/>
      </geometry>
      <origin rpy="0 0. 0" xyz="0 0 0"/>
      <material name="red">
        <color rgba="1.0 0.0 0.0 1.0"/>
      </material>
    </visual>
    <collision>
      <geometry>
        <sphere radius="0.14"/>
      </geometry>
      <origin rpy="0 0 0" xyz="0 0 0"/>
    </collision>
    <inertial>
      <mass value="0.1"/>
      <origin rpy="0 0 0" xyz="0 0 0"/>
      <inertia ixx="0.001" ixy="0" ixz="0" iyy="0.001" iyz="0" izz="0.001"/>
    </inertial>
  </link>
  <joint name="y_joint" type="continuous">
    <origin rpy="0 0 0" xyz="0 0 0.77"/>
    <axis xyz="0 1 0"/>
    <parent link="upperarm"/>
    <child link="upperball"/>
  </joint>
  <transmission name="trany">
    <type>transmission_interface/SimpleTransmission</type>
    <joint name="y_joint">
      <hardwareInterface>hardware_interface/PositionJointInterface</hardwareInterface>
    </joint>
    <actuator name="motory">
      <hardwareInterface>hardware_interface/PositionJointInterface</hardwareInterface>
      <mechanicalReduction>1</mechanicalReduction>
    </actuator>
  </transmission>
  <link name="middlearm">
    <visual>
      <geometry>
        <box size="0.14 0.14 0.7"/>
      </geometry>
      <origin rpy="0 0 0" xyz="0 0 0.35"/>
      <material name="white">
        <color rgba="1 1 1 1"/>
      </material>
    </visual>
    <collision>
      <geometry>
        <box size="0.14 0.14 0.56"/>
      </geometry>
      <origin rpy="0 0 0" xyz="0 0 0.42"/>
    </collision>
    <inertial>
      <mass value="1.6"/>
      <origin rpy="0 0 0" xyz="0 0 0"/>
      <inertia ixx="0.006051" ixy="0" ixz="0" iyy="0.002" iyz="0" izz="0.009098"/>
    </inertial>
  </link>
  <joint name="uball_joint" type="continuous">
    <origin rpy="0 0 0" xyz="0 0 0.09898"/>
    <axis xyz="0 0 1"/>
    <parent link="upperball"/>
    <child link="middlearm"/>
  </joint>
  <transmission name="tranub">
    <type>transmission_interface/SimpleTransmission</type>
    <joint name="uball_joint">
      <hardwareInterface>hardware_interface/PositionJointInterface</hardwareInterface>
    </joint>
    <actuator name="motorub">
      <hardwareInterface>hardware_interface/PositionJointInterface</hardwareInterface>
      <mechanicalReduction>1</mechanicalReduction>
    </actuator>
  </transmission>
  <link name="middleball">
    <visual>
      <geometry>
        <sphere radius="0.14"/>
      </geometry>
      <origin rpy="0 0. 0" xyz="0 0 0"/>
      <material name="red">
        <color rgba="1.0 0.0 0.0 1.0"/>
      </material>
    </visual>
    <collision>
      <geometry>
        <sphere radius="0.14"/>
      </geometry>
      <origin rpy="0 0 0" xyz="0 0 0"/>
    </collision>
    <inertial>
      <mass value="0.1"/>
      <origin rpy="0 0 0" xyz="0 0 0"/>
      <inertia ixx="0.001" ixy="0" ixz="0" iyy="0.001" iyz="0" izz="0.001"/>
    </inertial>
  </link>
  <joint name="x_joint" type="continuous">
    <origin rpy="0 0 0" xyz="0 0 0.77"/>
    <axis xyz="1 0 0"/>
    <parent link="middlearm"/>
    <child link="middleball"/>
  </joint>
  <transmission name="tranx">
    <type>transmission_interface/SimpleTransmission</type>
    <joint name="x_joint">
      <hardwareInterface>hardware_interface/PositionJointInterface</hardwareInterface>
    </joint>
    <actuator name="motorx">
      <hardwareInterface>hardware_interface/PositionJointInterface</hardwareInterface>
      <mechanicalReduction>1</mechanicalReduction>
    </actuator>
  </transmission>
  <link name="lowerarm">
    <visual>
      <geometry>
        <box size="0.28 0.07 0.7"/>
      </geometry>
      <origin rpy="0 0 0" xyz="0 0 0.35"/>
      <material name="gray">
        <color rgba="0.8 0.8 0.8 0.5"/>
      </material>
    </visual>
    <collision>
      <geometry>
        <box size="0.28 0.07 0.56"/>
      </geometry>
      <origin rpy="0 0 0" xyz="0 0 0.42"/>
    </collision>
    <inertial>
      <mass value="1.6"/>
      <origin rpy="0 0 0" xyz="0 0 0"/>
      <inertia ixx="0.006051" ixy="0" ixz="0" iyy="0.002" iyz="0" izz="0.009098"/>
    </inertial>
  </link>
  <joint name="mball_joint" type="continuous">
    <origin rpy="0 0 0" xyz="0 0 0.09898"/>
    <axis xyz="0 0 1"/>
    <parent link="middleball"/>
    <child link="lowerarm"/>
  </joint>
  <transmission name="tranmb">
    <type>transmission_interface/SimpleTransmission</type>
    <joint name="mball_joint">
      <hardwareInterface>hardware_interface/PositionJointInterface</hardwareInterface>
    </joint>
    <actuator name="motormb">
      <hardwareInterface>hardware_interface/PositionJointInterface</hardwareInterface>
      <mechanicalReduction>1</mechanicalReduction>
    </actuator>
  </transmission>
  <link name="wrist">
    <visual>
      <geometry>
        <cylinder length="0.035" radius="0.21"/>
      </geometry>
      <origin rpy="0 1.57 0" xyz="0. 0. 0."/>
      <material name="red">
        <color rgba="1.0 0.0 0.0 1.0"/>
      </material>
    </visual>
    <collision>
      <geometry>
        <cylinder length="0.035" radius="0.21"/>
      </geometry>
      <origin rpy="0 1.57 0" xyz="0. 0. 0."/>
    </collision>
    <inertial>
      <mass value="0.6"/>
      <origin rpy="0 0 0" xyz="0 0 0"/>
      <inertia ixx="0.002051" ixy="0" ixz="0" iyy="0.001" iyz="0" izz="0.003098"/>
    </inertial>
  </link>
  <joint name="wrist_joint" type="prismatic">
    <origin rpy="0 0 0" xyz="0. 0. 0.742"/>
    <axis xyz="1 0 0"/>
    <parent link="lowerarm"/>
    <child link="wrist"/>
    <limit effort="100" lower="-0.105" upper="0.105" velocity="1.0"/>
  </joint>
  <transmission name="tranwr">
    <type>transmission_interface/SimpleTransmission</type>
    <joint name="wrist_joint">
      <hardwareInterface>hardware_interface/PositionJointInterface</hardwareInterface>
    </joint>
    <actuator name="motorwr">
      <hardwareInterface>hardware_interface/PositionJointInterface</hardwareInterface>
      <mechanicalReduction>1</mechanicalReduction>
    </actuator>
  </transmission>
  <link name="hand">
    <visual>
      <geometry>
        <box size="0.3 0.05 0.4"/>
      </geometry>
      <origin rpy="0 0 0" xyz="0.05 0. 0.2"/>
      <material name="blue">
        <color rgba="0.0 0.0 1.0 1"/>
      </material>
    </visual>
    <collision>
      <geometry>
        <box size="0.3 0.05 0.4"/>
      </geometry>
      <origin rpy="0 0 0" xyz="0.05 0. 0.2"/>
    </collision>
    <inertial>
      <mass value="0.6"/>
      <origin rpy="0 0 0" xyz="0 0 0"/>
      <inertia ixx="0.002051" ixy="0" ixz="0" iyy="0.001" iyz="0" izz="0.003098"/>
    </inertial>
  </link>
  <joint name="hand_joint" type="continuous">
    <origin rpy="0 0 0" xyz="0. 0. 0.05"/>
    <axis xyz="1 0 0"/>
    <parent link="wrist"/>
    <child link="hand"/>
  </joint>
  <transmission name="tranhj">
    <type>transmission_interface/SimpleTransmission</type>
    <joint name="hand_joint">
      <hardwareInterface>hardware_interface/PositionJointInterface</hardwareInterface>
    </joint>
    <actuator name="motorhj">
      <hardwareInterface>hardware_interface/PositionJointInterface</hardwareInterface>
      <mechanicalReduction>1</mechanicalReduction>
    </actuator>
  </transmission>
  <link name="dummy_finger">
    <visual>
      <geometry>
        <box size="0.01 0.01 0.2"/>
      </geometry>
      <origin rpy="0 0 0" xyz="0.005 0.005 0.1"/>
      <material name="green">
        <color rgba="0.0 1.0 0.0 1"/>
      </material>
    </visual>
    <collision>
      <geometry>
        <box size="0.01 0.01 0.2"/>
      </geometry>
      <origin rpy="0 0 0" xyz="0. 0. 0.1"/>
    </collision>
    <inertial>
      <mass value="0.0006"/>
      <origin rpy="0 0 0" xyz="0 0 0"/>
      <inertia ixx="0.00002051" ixy="0" ixz="0" iyy="0.00001" iyz="0" izz="0.00003098"/>
    </inertial>
  </link>
  <!-- <link name="dummy_finger"/> -->
  <joint name="f1_z_pris" type="prismatic">
    <origin rpy="0 0 0" xyz="0.2 0.025 0.2"/>
    <axis xyz="0 0 1"/>
    <parent link="hand"/>
    <child link="dummy_finger"/>
    <limit effort="30" lower="-0.2" upper="0" velocity="30.0"/>
  </joint>
  <transmission name="tranf1zpj">
    <type>transmission_interface/SimpleTransmission</type>
    <joint name="f1_z_pris">
      <hardwareInterface>hardware_interface/PositionJointInterface</hardwareInterface>
    </joint>
    <actuator name="motorf1zpj">
      <hardwareInterface>hardware_interface/PositionJointInterface</hardwareInterface>
      <mechanicalReduction>1</mechanicalReduction>
    </actuator>
  </transmission>
  <link name="finger1">
    <visual>
      <geometry>
        <box size="0.15 0.05 0.2"/>
      </geometry>
      <origin rpy="0 0 0" xyz="-0.075 0.025 0.1"/>
      <material name="blue"/>
    </visual>
    <collision>
      <geometry>
        <box size="0.15 0.05 0.2"/>
      </geometry>
      <origin rpy="0 0 0" xyz="-0.075 0.025 0.1"/>
    </collision>
    <inertial>
      <mass value="0.6"/>
      <origin rpy="0 0 0" xyz="0 0 0"/>
      <inertia ixx="0.002051" ixy="0" ixz="0" iyy="0.001" iyz="0" izz="0.003098"/>
    </inertial>
  </link>
  <joint name="f1_joint" type="revolute">
    <origin rpy="0 0 0" xyz="0 0 0"/>
    <axis xyz="0 0 1"/>
    <parent link="dummy_finger"/>
    <child link="finger1"/>
    <limit effort="30" lower="-3.14" upper="0" velocity="3.14"/>
  </joint>
  <transmission name="tranf1j">
    <type>transmission_interface/SimpleTransmission</type>
    <joint name="f1_joint">
      <hardwareInterface>hardware_interface/PositionJointInterface</hardwareInterface>
    </joint>
    <actuator name="motorf1j">
      <hardwareInterface>hardware_interface/PositionJointInterface</hardwareInterface>
      <mechanicalReduction>1</mechanicalReduction>
    </actuator>
  </transmission>
  <link name="finger2">
    <visual>
      <geometry>
        <box size="0.1 0.05 0.08"/>
      </geometry>
      <origin rpy="0 0 0" xyz="-0.05 0.025 0.04"/>
      <material name="green"/>
    </visual>
    <collision>
      <geometry>
        <box size="0.1 0.05 0.08"/>
      </geometry>
      <origin rpy="0 0 0" xyz="-0.05 0.025 0.04"/>
    </collision>
    <inertial>
      <mass value="0.1"/>
      <origin rpy="0 0 0" xyz="0 0 0"/>
      <inertia ixx="0.0002051" ixy="0" ixz="0" iyy="0.0001" iyz="0" izz="0.0003098"/>
    </inertial>
  </link>
  <joint name="f2_joint" type="revolute">
    <origin rpy="0 0 0" xyz="-0.05 -0.0 0.2"/>
    <axis xyz="1 0 0"/>
    <parent link="finger1"/>
    <child link="finger2"/>
    <limit effort="30" lower="0" upper="3.14" velocity="3.14"/>
  </joint>
  <transmission name="tranf2j">
    <type>transmission_interface/SimpleTransmission</type>
    <joint name="f2_joint">
      <hardwareInterface>hardware_interface/PositionJointInterface</hardwareInterface>
    </joint>
    <actuator name="motorf2j">
      <hardwareInterface>hardware_interface/PositionJointInterface</hardwareInterface>
      <mechanicalReduction>1</mechanicalReduction>
    </actuator>
  </transmission>
  <link name="finger3">
    <visual>
      <geometry>
        <box size="0.1 0.05 0.08"/>
      </geometry>
      <origin rpy="0 0 0" xyz="-0.05 0.025 0.04"/>
      <material name="blue"/>
    </visual>
    <collision>
      <geometry>
        <box size="0.1 0.05 0.08"/>
      </geometry>
      <origin rpy="0 0 0" xyz="-0.05 0.025 0.04"/>
    </collision>
    <inertial>
      <mass value="0.1"/>
      <origin rpy="0 0 0" xyz="0 0 0"/>
      <inertia ixx="0.0002051" ixy="0" ixz="0" iyy="0.0001" iyz="0" izz="0.0003098"/>
    </inertial>
  </link>
  <joint name="f3_joint" type="revolute">
    <origin rpy="0 0 0" xyz="-0.0 -0.0 0.08"/>
    <axis xyz="1 0 0"/>
    <parent link="finger2"/>
    <child link="finger3"/>
    <limit effort="30" lower="0" upper="3.14" velocity="3.14"/>
  </joint>
  <transmission name="tranf3j">
    <type>transmission_interface/SimpleTransmission</type>
    <joint name="f3_joint">
      <hardwareInterface>hardware_interface/PositionJointInterface</hardwareInterface>
    </joint>
    <actuator name="motorf3j">
      <hardwareInterface>hardware_interface/PositionJointInterface</hardwareInterface>
      <mechanicalReduction>1</mechanicalReduction>
    </actuator>
  </transmission>
  <link name="finger4">
    <visual>
      <geometry>
        <box size="0.1 0.05 0.08"/>
      </geometry>
      <origin rpy="0 0 0" xyz="-0.05 0.025 0.04"/>
      <material name="green"/>
    </visual>
    <collision>
      <geometry>
        <box size="0.1 0.05 0.08"/>
      </geometry>
      <origin rpy="0 0 0" xyz="-0.05 0.025 0.04"/>
    </collision>
    <inertial>
      <mass value="0.1"/>
      <origin rpy="0 0 0" xyz="0 0 0"/>
      <inertia ixx="0.0002051" ixy="0" ixz="0" iyy="0.0001" iyz="0" izz="0.0003098"/>
    </inertial>
  </link>
  <joint name="f4_joint" type="revolute">
    <origin rpy="0 0 0" xyz="-0.0 -0.0 0.08"/>
    <axis xyz="1 0 0"/>
    <parent link="finger3"/>
    <child link="finger4"/>
    <limit effort="30" lower="0" upper="3.14" velocity="3.14"/>
  </joint>
  <transmission name="tranf4j">
    <type>transmission_interface/SimpleTransmission</type>
    <joint name="f4_joint">
      <hardwareInterface>hardware_interface/PositionJointInterface</hardwareInterface>
    </joint>
    <actuator name="motorf4j">
      <hardwareInterface>hardware_interface/PositionJointInterface</hardwareInterface>
      <mechanicalReduction>1</mechanicalReduction>
    </actuator>
  </transmission>
  <link name="finger5">
    <visual>
      <geometry>
        <box size="0.1 0.05 0.08"/>
      </geometry>
      <origin rpy="0 0 0" xyz="-0.05 0.025 0.04"/>
      <material name="blue"/>
    </visual>
    <collision>
      <geometry>
        <box size="0.1 0.05 0.08"/>
      </geometry>
      <origin rpy="0 0 0" xyz="-0.05 0.025 0.04"/>
    </collision>
    <inertial>
      <mass value="0.1"/>
      <origin rpy="0 0 0" xyz="0 0 0"/>
      <inertia ixx="0.0002051" ixy="0" ixz="0" iyy="0.0001" iyz="0" izz="0.0003098"/>
    </inertial>
  </link>
  <joint name="f5_joint" type="revolute">
    <origin rpy="0 0 0" xyz="-0.0 -0.0 0.08"/>
    <axis xyz="1 0 0"/>
    <parent link="finger4"/>
    <child link="finger5"/>
    <limit effort="30" lower="0" upper="3.14" velocity="3.14"/>
  </joint>
  <transmission name="tranf5j">
    <type>transmission_interface/SimpleTransmission</type>
    <joint name="f5_joint">
      <hardwareInterface>hardware_interface/PositionJointInterface</hardwareInterface>
    </joint>
    <actuator name="motorf5j">
      <hardwareInterface>hardware_interface/PositionJointInterface</hardwareInterface>
      <mechanicalReduction>1</mechanicalReduction>
    </actuator>
  </transmission>
  <link name="finger6">
    <visual>
      <geometry>
        <box size="0.1 0.05 0.08"/>
      </geometry>
      <origin rpy="0 0 0" xyz="-0.05 0.025 0.04"/>
      <material name="green"/>
    </visual>
    <collision>
      <geometry>
        <box size="0.1 0.05 0.08"/>
      </geometry>
      <origin rpy="0 0 0" xyz="-0.05 0.025 0.04"/>
    </collision>
    <inertial>
      <mass value="0.1"/>
      <origin rpy="0 0 0" xyz="0 0 0"/>
      <inertia ixx="0.0002051" ixy="0" ixz="0" iyy="0.0001" iyz="0" izz="0.0003098"/>
    </inertial>
  </link>
  <joint name="f6_joint" type="revolute">
    <origin rpy="0 0 0" xyz="-0.0 -0.0 0.08"/>
    <axis xyz="1 0 0"/>
    <parent link="finger5"/>
    <child link="finger6"/>
    <limit effort="30" lower="0" upper="3.14" velocity="3.14"/>
  </joint>
  <transmission name="tranf6j">
    <type>transmission_interface/SimpleTransmission</type>
    <joint name="f6_joint">
      <hardwareInterface>hardware_interface/PositionJointInterface</hardwareInterface>
    </joint>
    <actuator name="motorf6j">
      <hardwareInterface>hardware_interface/PositionJointInterface</hardwareInterface>
      <mechanicalReduction>1</mechanicalReduction>
    </actuator>
  </transmission>
  <link name="fingerend">
    <visual>
      <geometry>
        <cylinder length="0.02" radius="0.03"/>
      </geometry>
      <origin rpy="0 0 0" xyz="0 0 0.01"/>
      <material name="red"/>
    </visual>
    <collision>
      <geometry>
        <cylinder length="0.02" radius="0.03"/>
      </geometry>
      <origin rpy="0 0 0" xyz="0 0 0.01"/>
    </collision>
    <inertial>
      <mass value="0.06"/>
      <origin rpy="0 0 0" xyz="0 0 0.0"/>
      <inertia ixx="0.0006051" ixy="0" ixz="0" iyy="0.0002" iyz="0" izz="0.0009098"/>
    </inertial>
  </link>
  <joint name="fe_joint" type="continuous">
    <origin rpy="0 0 0" xyz="-0.09 0.025 0.08"/>
    <axis xyz="0 0 1"/>
    <parent link="finger6"/>
    <child link="fingerend"/>
  </joint>
  <transmission name="tranfej">
    <type>transmission_interface/SimpleTransmission</type>
    <joint name="fe_joint">
      <hardwareInterface>hardware_interface/PositionJointInterface</hardwareInterface>
    </joint>
    <actuator name="motorfej">
      <hardwareInterface>hardware_interface/PositionJointInterface</hardwareInterface>
      <mechanicalReduction>1</mechanicalReduction>
    </actuator>
  </transmission>
  <link name="end_arm"/>
  <joint name="end_arm_joint" type="fixed">
    <origin rpy="0 0 0" xyz="-0.18 0.05 0.2"/>
    <parent link="finger1"/>
    <child link="end_arm"/>
  </joint>
  <link name="end_hand"/>
  <joint name="end_hand_joint" type="fixed">
    <origin rpy="0 0 0" xyz="0 0 0.02"/>
    <parent link="fingerend"/>
    <child link="end_hand"/>
  </joint>
  <gazebo>
    <plugin filename="libgazebo_ros_joint_state_publisher.so" name="joint_state_publisher">
      <jointName>base_joint,y_joint,uball_joint,x_joint,mball_joint,wrist_joint,hand_joint,f1_z_pris,f1_joint,f2_joint,f3_joint,f4_joint,f5_joint,f6_joint,fe_joint</jointName>
    </plugin>
  </gazebo>
  <!-- <gazebo>
          <plugin name="differential_drive_controller" filename="libgazebo_ros_diff_drive.so">
          <leftJoint>base_joint</leftJoint>
          <rightJoint>y_joint</rightJoint>
          <robotBaseFrame>upperarm</robotBaseFrame>
          <wheelSeparation>0.236</wheelSeparation>
          <wheelDiameter>0.17</wheelDiameter>
          <publishWheelJointState>true</publishWheelJointState>
          <legacyMode>false</legacyMode>
          <commandTopic>cmd_vel</commandTopic>
          <odometryTopic>odom</odometryTopic>
          <odometryFrame>odom</odometryFrame>
          <odometrySource>world</odometrySource>
          <publishOdomTF>true</publishOdomTF>
          <publishWheelTF>false</publishWheelTF>
          <publishTf>true</publishTf>
          <updateRate>30</updateRate>
          <wheelAcceleration>1</wheelAcceleration>
          <wheelTorque>10</wheelTorque>
          <rosDebugLevel>na</rosDebugLevel>
          </plugin>
        </gazebo> -->
  <gazebo>
    <plugin filename="libgazebo_ros_control.so" name="gazebo_ros_control">
      <robotNamespace>/</robotNamespace>
      <controlPeriod>0.001</controlPeriod>
      <robotSimType>gazebo_ros_control/DefaultRobotHWSim</robotSimType>
      <legacyModeNS>true</legacyModeNS>
    </plugin>
  </gazebo>
</robot>

