<robot name="test_robot" xmlns:xacro="http://ros.org/wiki/xacro">
        <link name="base">
          <visual>
            <geometry>
              <box size="1 1 0.1" />
            </geometry>
            <origin xyz="0 0 0.05" rpy="0 0 0"/>
            <material name="white">
              <color rgba="1 1 1 1"/>
            </material>
          </visual>
          <collision>
            <geometry>
                <box size="1 1 0.1" />
            </geometry>
            <origin xyz="0 0 0.05" rpy="0 0 0"/>
          </collision>
          <inertial>
            <mass value="1.6"/>
            <origin xyz="0 0 0" rpy="0 0 0"/>
            <inertia ixx="0.006051" iyy="0" izz="0.009098" ixy="0" ixz="0" iyz="0"/>
          </inertial>
        </link>

        <link name="upperarm">
          <visual>
            <geometry>
              <cylinder length="1" radius="0.05"/>
            </geometry>
            <origin xyz="0 0 0.5" rpy="0 0 0"/>
            <material name="white">
              <color rgba="1 1 1 1"/>
            </material>
          </visual>
          <collision>
            <geometry>
                <cylinder length="1" radius="0.05"/>
            </geometry>
            <origin xyz="0 0 0.5" rpy="0 0 0"/>
          </collision>
          <inertial>
            <mass value="1.6"/>
            <origin xyz="0 0 0" rpy="0 0 0"/>
            <inertia ixx="0.006051" iyy="0" izz="0.009098" ixy="0" ixz="0" iyz="0"/>
          </inertial>
        </link>

        <joint name="base_joint" type="continuous">
            <origin xyz="0 0 0" rpy="0 0 0"/>
            <axis xyz="0 0 1"/>
            <parent link="base"/>
            <child link="upperarm" />
        </joint>

        <link name="lowerarm">
          <visual>
            <geometry>
              <box size="0.1 0.1 1.2" />
            </geometry>
            <origin xyz="0 0 0.4" rpy="0 0 0"/>
            <material name="gray">
                <color rgba="0.8 0.8 0.8 0.5"/>
            </material>
          </visual>
          <collision>
            <geometry>
                <box size="0.1 0.1 1.2" />
            </geometry>
            <origin xyz="0 0 0.4" rpy="0 0 0"/>
          </collision>
          <inertial>
            <mass value="1.6"/>
            <origin xyz="0 0 0" rpy="0 0 0"/>
            <inertia ixx="0.006051" iyy="0" izz="0.009098" ixy="0" ixz="0" iyz="0"/>
          </inertial>
        </link>

        <joint name="y_joint" type="continuous">
            <origin xyz="0 0.1 0.95" rpy="0 0 0"/>
            <axis xyz="0 1 0"/>
            <parent link="upperarm"/>
            <child link="lowerarm"/>
        </joint>
        <gazebo>
          <plugin name="joint_state_publisher" filename="libgazebo_ros_joint_state_publisher.so">
          <jointName>base_joint,y_joint</jointName>
          </plugin>
        </gazebo>
        <gazebo>
          <plugin name="differential_drive_controller" filename="libgazebo_ros_diff_drive.so">
          <leftJoint>base_joint</leftJoint>
          <rightJoint>y_joint</rightJoint>
          <robotBaseFrame>upperarm</robotBaseFrame>
          <wheelSeparation>0.236</wheelSeparation>
          <wheelDiameter>0.17</wheelDiameter>
          <publishWheelJointState>true</publishWheelJointState>
          <legacyMode>false</legacyMode>
          <commandTopic>cmd_vel</commandTopic>
          <odometryTopic>odom</odometryTopic>
          <odometryFrame>odom</odometryFrame>
          <odometrySource>world</odometrySource>
          <publishOdomTF>true</publishOdomTF>
          <publishWheelTF>false</publishWheelTF>
          <publishTf>true</publishTf>
          <updateRate>30</updateRate>
          <wheelAcceleration>1</wheelAcceleration>
          <wheelTorque>10</wheelTorque>
          <rosDebugLevel>na</rosDebugLevel>
          </plugin>
        </gazebo>
        <!-- <gazebo>
          <plugin name="gazebo_ros_control" filename="libgazebo_ros_control.so">
            <robotNamespace>/</robotNamespace>
            <controlPeriod>0.001</controlPeriod>
            <robotSimType>gazebo_ros_control/DefaultRobotHWSim</robotSimType>
            <legacyModeNS>true</legacyModeNS>
          </plugin>
        </gazebo> -->
</robot>
