<?xml version="1.0" encoding="utf-8"?>
<!-- =================================================================================== -->
<!-- |    This document was autogenerated by xacro from arm_urdf_kobuki.xacro          | -->
<!-- |    EDITING THIS FILE BY HAND IS NOT RECOMMENDED                                 | -->
<!-- =================================================================================== -->
<robot name="test_robot">
  <link name="base">
    <visual>
      <geometry>
        <box size="1 1 0.1"/>
      </geometry>
      <origin rpy="0 0 0" xyz="0 0 0.05"/>
      <material name="white">
        <color rgba="1 1 1 1"/>
      </material>
    </visual>
    <collision>
      <geometry>
        <box size="1 1 0.1"/>
      </geometry>
      <origin rpy="0 0 0" xyz="0 0 0.05"/>
    </collision>
    <inertial>
      <mass value="1.6"/>
      <origin rpy="0 0 0" xyz="0 0 0"/>
      <inertia ixx="0.006051" ixy="0" ixz="0" iyy="0" iyz="0" izz="0.009098"/>
    </inertial>
  </link>
  <link name="upperarm">
    <visual>
      <geometry>
        <cylinder length="1" radius="0.05"/>
      </geometry>
      <origin rpy="0 0 0" xyz="0 0 0.5"/>
      <material name="white">
        <color rgba="1 1 1 1"/>
      </material>
    </visual>
    <collision>
      <geometry>
        <cylinder length="1" radius="0.05"/>
      </geometry>
      <origin rpy="0 0 0" xyz="0 0 0.5"/>
    </collision>
    <inertial>
      <mass value="1.6"/>
      <origin rpy="0 0 0" xyz="0 0 0"/>
      <inertia ixx="0.006051" ixy="0" ixz="0" iyy="0" iyz="0" izz="0.009098"/>
    </inertial>
  </link>
  <joint name="base_joint" type="continuous">
    <origin rpy="0 0 0" xyz="0 0 0"/>
    <axis xyz="0 0 1"/>
    <parent link="base"/>
    <child link="upperarm"/>
  </joint>
  <link name="lowerarm">
    <visual>
      <geometry>
        <box size="0.1 0.1 1.2"/>
      </geometry>
      <origin rpy="0 0 0" xyz="0 0 0.4"/>
      <material name="gray">
        <color rgba="0.8 0.8 0.8 0.5"/>
      </material>
    </visual>
    <collision>
      <geometry>
        <box size="0.1 0.1 1.2"/>
      </geometry>
      <origin rpy="0 0 0" xyz="0 0 0.4"/>
    </collision>
    <inertial>
      <mass value="1.6"/>
      <origin rpy="0 0 0" xyz="0 0 0"/>
      <inertia ixx="0.006051" ixy="0" ixz="0" iyy="0" iyz="0" izz="0.009098"/>
    </inertial>
  </link>
  <joint name="y_joint" type="continuous">
    <origin rpy="0 0 0" xyz="0 0.1 0.95"/>
    <axis xyz="0 1 0"/>
    <parent link="upperarm"/>
    <child link="lowerarm"/>
  </joint>
  <gazebo>
    <plugin filename="libgazebo_ros_joint_state_publisher.so" name="joint_state_publisher">
      <jointName>base_joint,y_joint</jointName>
    </plugin>
  </gazebo>
  <gazebo>
    <plugin filename="libgazebo_ros_diff_drive.so" name="differential_drive_controller">
      <leftJoint>base_joint</leftJoint>
      <rightJoint>y_joint</rightJoint>
      <robotBaseFrame>upperarm</robotBaseFrame>
      <wheelSeparation>0.236</wheelSeparation>
      <wheelDiameter>0.17</wheelDiameter>
      <publishWheelJointState>true</publishWheelJointState>
      <legacyMode>false</legacyMode>
      <commandTopic>cmd_vel</commandTopic>
      <odometryTopic>odom</odometryTopic>
      <odometryFrame>odom</odometryFrame>
      <odometrySource>world</odometrySource>
      <publishOdomTF>true</publishOdomTF>
      <publishWheelTF>false</publishWheelTF>
      <publishTf>true</publishTf>
      <updateRate>30</updateRate>
      <wheelAcceleration>1</wheelAcceleration>
      <wheelTorque>10</wheelTorque>
      <rosDebugLevel>na</rosDebugLevel>
    </plugin>
  </gazebo>
  <!-- <gazebo>
          <plugin name="gazebo_ros_control" filename="libgazebo_ros_control.so">
            <robotNamespace>/</robotNamespace>
            <controlPeriod>0.001</controlPeriod>
            <robotSimType>gazebo_ros_control/DefaultRobotHWSim</robotSimType>
            <legacyModeNS>true</legacyModeNS>
          </plugin>
        </gazebo> -->
</robot>

